Workbook

Sheet Drop Down Lists
A1: PERF | B1: MECH | C1: Territories
A2: ABRAMUS | B2: ABRAMUS | C2: Argentina
A3: AKM-AUME | B3: AKM-AUME | C3: Australia
A4: AMRA | B4: AMRA | C4: Austria
A5: APDAYC | B5: APDAYC | C5: Belgium
A6: APRA-AMCOS | B6: APRA-AMCOS | C6: Bolivia
A7: ASCAP | B7: ASCAP | C7: Brazil
A8: BMI | B8: BMI | C8: Canada
A9: BUMA | B9: BUMA | C9: Chile
A10: CASH | B10: CASH | C10: China
A11: COMPASS | B11: COMPASS | C11: Colombia
A12: GEMA | B12: GEMA | C12: Costa Rica
... A31: SUISA | B31: SUISA | C31: Peru
C32: Philippines
C33: Poland
C34: Portugal
C35: Russia
C36: Singapore
C37: South Africa
C38: South Korea
C39: Spain
C40: Sweden
C41: Switzerland
C42: Taiwan
C43: Thailand
... C49: Vietnam

Sheet MATRIX CALCULATOR
G1: PERFORMANCE | K1: MECHANICAL
B2: Last updated 29/07/2024
B3: PERF AFFILIATION | D3: USAGE TERRITORY | G3: ONLINE - MULTI-TERRITORY (eg. Spotify, Apple Music, YouTube etc...) | K3: ONLINE - MULTI-TERRITORY (eg. Spotify, Apple Music, YouTube etc...)
G4: LICENSED BY: | H4: LICENSOR PAYS: | I4: KOBALT PAID BY: | K4: LICENSED BY: | L4: LICENSOR PAYS: | M4: KOBALT PAID BY:
B5: SOCAN | D5: United Kingdom | G5: {=INDEX('Licensed By Table'!C2:AX35,MATCH(B5,'Licensed By Table'!A2:A35,0),MATCH(D5,'Licensed By Table'!C1:AX1,0))} -> AMRA | H5: {=INDEX('Licensor Pays Table'!C2:AX35,MATCH(B5,'Licensor Pays Table'!A2:A35,0),MATCH(D5,'Licensor Pays Table'!C1:AX1,0))} -> AMRA | I5: {=INDEX('Paid By Table'!C2:AX35, MATCH(B5,'Paid By Table'!A2:A35,0),MATCH(D5,'Paid By Table'!C1:AX1,0))} -> AMRA | K5: {=INDEX('MECH - Licensed By'!C2:AX35,MATCH(B8,'MECH - Licensed By'!A2:A35,0),MATCH(D5,'MECH - Licensed By'!C1:AX1,0))} -> ICE | L5: {=INDEX('MECH - Licensor Pays'!C2:AX35,MATCH(B8,'MECH - Licensor Pays'!A2:A35,0),MATCH(D5,'MECH - Licensor Pays'!C1:AX1,0))} -> AUME | M5: {=INDEX('MECH - Paid By'!C2:AX35, MATCH(B8,'MECH - Paid By'!A2:A35,0),MATCH(D5,'MECH - Paid By'!C1:AX1,0))} -> MCPS-PRS
B6: MECH AFFILIATION | D6: # | G6: =IF(D6=TRUE,"PLEASE NOTE ALL INCOME FOR EUROPE IS PAID DIRECT TO KOBALT FROM WRITER'S AFFILIATED SOCIETY","")
B8: AKM-AUME | G8: ONLINE - AV (eg. Netflix, Amazon Prime Video...) | K8: ONLINE - AV (eg. Netflix, Amazon Prime Video...)
G9: LICENSED BY: | H9: LICENSOR PAYS: | I9: KOBALT PAID BY: | K9: LICENSED BY: | L9: LICENSOR PAYS: | M9: KOBALT PAID BY:
B10: LICENSING & REVENUE PIPELINE MATRIX | G10: =VLOOKUP($D$5,'Offline Matrix'!A:E,2,false) -> PRS | H10: =VLOOKUP($D$5,'Offline Matrix'!A:E,4,false) -> PRS | I10: =H10 -> PRS | K10: =VLOOKUP($D$5,'Offline Matrix'!A:E,3,false) -> MCPS | L10: =VLOOKUP($D$5,'Offline Matrix'!A:E,5,false) -> MCPS | M10: =L10 -> MCPS
G12: ONLINE - Local (Available in single territory) | K12: ONLINE - Local (Available in single territory)
G13: LICENSED BY: | H13: LICENSOR PAYS: | I13: KOBALT PAID BY: | K13: LICENSED BY: | L13: LICENSOR PAYS: | M13: KOBALT PAID BY:
G14: =VLOOKUP($D$5,'Offline Matrix'!A:E,2,false) -> PRS | H14: =VLOOKUP($D$5,'Offline Matrix'!A:E,4,false) -> PRS | I14: =H14 -> PRS | K14: =VLOOKUP($D$5,'Offline Matrix'!A:E,3,false) -> MCPS | L14: =VLOOKUP($D$5,'Offline Matrix'!A:E,5,false) -> MCPS | M14: =L14 -> MCPS
G16: BROADCAST - TV | K16: BROADCAST - TV
H17: LICENSOR PAYS: | I17: KOBALT PAID BY: | K17: LICENSED BY: | L17: LICENSOR PAYS: | M17: KOBALT PAID BY:
G18: =VLOOKUP($D$5,'Offline Matrix'!A:E,2,false) -> PRS | H18: =VLOOKUP($D$5,'Offline Matrix'!A:E,4,false) -> PRS | I18: =H18 -> PRS | K18: =VLOOKUP($D$5,'Offline Matrix'!A:E,3,false) -> MCPS | L18: =VLOOKUP($D$5,'Offline Matrix'!A:E,5,false) -> MCPS | M18: =L18 -> MCPS
G20: BROADCAST - RADIO | K20: BROADCAST - RADIO
G21: LICENSED BY: | H21: LICENSOR PAYS: | I21: KOBALT PAID BY: | K21: LICENSED BY: | L21: LICENSOR PAYS: | M21: KOBALT PAID BY:
G22: =VLOOKUP($D$5,'Offline Matrix'!A:E,2,false) -> PRS | H22: =VLOOKUP($D$5,'Offline Matrix'!A:E,4,false) -> PRS | I22: =H22 -> PRS | K22: =VLOOKUP($D$5,'Offline Matrix'!A:E,3,false) -> MCPS | L22: =VLOOKUP($D$5,'Offline Matrix'!A:E,5,false) -> MCPS | M22: =L22 -> MCPS
G24: PUBLIC PERFORMANCE - LIVE | K24: MECHANICAL REPRODUCTION
G25: LICENSED BY: | H25: LICENSOR PAYS: | I25: KOBALT PAID BY: | K25: LICENSED BY: | L25: LICENSOR PAYS: | M25: KOBALT PAID BY:
G26: =VLOOKUP($D$5,'Offline Matrix'!A:E,2,false) -> PRS | H26: =VLOOKUP($D$5,'Offline Matrix'!A:E,4,false) -> PRS | I26: =H26 -> PRS | K26: =IF($D$5="United States","Major Label / HFA ", IF(OR(D5 = "China",D5= "Hong Kong", D5 = "Thailand", D5 = "Philippines", D5 = "Singapore"),"Varies Consult Source Owner",VLOOKUP($D$5,'Offline Matrix'!A:E,3,false))) -> MCPS | L26: =IF($D$5="United States","Major Label / HFA",IF(OR(D5 = "China",D5= "Hong Kong", D5 = "Thailand", D5 = "Philippines", D5 = "Singapore"),"Varies Consult Source Owner", VLOOKUP($D$5,'Offline Matrix'!A:E,5,false))) -> MCPS | M26: =L26 -> MCPS
G28: PUBLIC PERFORMANCE - CINEMA
G29: LICENSED BY: | H29: LICENSOR PAYS: | I29: KOBALT PAID BY:
G30: =IF($D$5="United States","Not Licensed",VLOOKUP($D$5,'Offline Matrix'!A:E,2,FALSE)) -> PRS | H30: =IF($D$5="United States","Not Licensed",VLOOKUP($D$5,'Offline Matrix'!A:E,4,false)) -> PRS | I30: =H30 -> PRS
G32: PUBLIC PERFORMANCE - LICENSED PREMESES
G33: LICENSED BY: | H33: LICENSOR PAYS: | I33: KOBALT PAID BY:
G34: =VLOOKUP($D$5,'Offline Matrix'!A:E,2,false) -> PRS | H34: =VLOOKUP($D$5,'Offline Matrix'!A:E,4,false) -> PRS | I34: =H34 -> PRS

Sheet Matrix - PERF
A1: Licensed By: How our pub share is licensed Licensor Pays: First society income is paid to Kobalt Paid By: Pub share payment made to Kobalt | D1: PERFORMANCE INCOME - NOT INCLUDED IN DL
D2: EUROPE | W2: US / Canada | Y2: Latin America | AJ2: Australasia | AL2: Asia | AX2: Africa
A3: BIEM Rep (Example: 1 Writer -> Kobalt) | B3: SOCIETY | D3: Austria | E3: Belgium | F3: France | G3: Germany | H3: Italy | I3: Netherlands | J3: Nordics Finland / Norway / Iceland, etc) | K3: Portugal | L3: Spain | M3: Sweden | N3: Switzerland | O3: United Kingdom | P3: Croatia | Q3: Greece | R3: Poland | S3: Russia | T3: Israel | U3: UAE | V3: Turkey | W3: Canada | X3: United States | Y3: Argentina | Z3: Bolivia | AA3: Brazil | AB3: Chile | AC3: Colombia | AD3: Costa Rica | AE3: Ecuador | AF3: Mexico | AG3: Paraguay | AH3: Peru | AI3: Uruguay | AJ3: Australia | AK3: New Zealand | AL3: China | AM3: HongKong | AN3: India | AO3: Japan | AP3: Malaysia | AQ3: Philippines | AR3: Vietnam | AS3: Thailand | AT3: Singapore | AU3: South Korea | AV3: Indonesia | AW3: Taiwan | AX3: South Africa | AY3: North Africa
A4: AKM-AUME | B4: AKM-AUME | C4: Licensed By | D4: AKM | E4: ICE | F4: ICE | G4: ICE | H4: ICE | I4: ICE | J4: ICE | K4: ICE | L4: ICE | M4: ICE | N4: ICE | O4: ICE | P4: ICE | Q4: ICE | R4: ICE | S4: RAO | T4: ACUM | U4: ESMAA | V4: MSG | W4: SOCAN | X4: ASCAP/BMI/SESAC/GMR | Y4: SADAIC | Z4: Latin Autor | AA4: ECAD | AB4: Latin Autor | AC4: Latin Autor | AD4: Latin Autor | AE4: Latin Autor | AF4: SACM | AG4: Latin Autor | AH4: Latin Autor | AI4: Latin Autor | AJ4: APRA-AMCOS | AK4: APRA-AMCOS | AL4: MCSC | AM4: CASH | AO4: JASRAC | AP4: MACP | AQ4: FILSCAP | AR4: VCPMC | AS4: MCT | AT4: COMPASS | AU4: KOMCA | AW4: MUST | AX4: SAMRO | AY4: ICE
B5: AKM-AUME | C5: Licensor Pays | D5: AKM | E5: SABAM | F5: SACEM | G5: GEMA | H5: SIAE | I5: BUMA | J5: STIM | K5: SPA | L5: SGAE | M5: STIM | N5: SUISA | O5: MCPS-PRS | P5: HDS-ZAMP | Q5: AUTODIA | R5: ZAIKS | S5: Blue Sun | T5: Dalia | U5: Pop Arabia | V5: Zeplin | W5: SOCAN | X5: ASCAP/BMI/SESAC/GMR | Y5: SADAIC | Z5: Latin Autor (Processed by BO) | AA5: ECAD | AB5: Latin Autor (Processed by BO) | AC5: Latin Autor (Processed by BO) | AD5: Latin Autor (Processed by BO) | AE5: Latin Autor (Processed by BO) | AF5: SACM | AG5: Latin Autor (Processed by BO) | AH5: Latin Autor (Processed by BO) | AI5: Latin Autor (Processed by BO) | AJ5: APRA-AMCOS | AK5: APRA-AMCOS | AL5: MCSC | AM5: CASH | AO5: JASRAC | AP5: MACP | AQ5: FILSCAP | AR5: VCPMC | AS5: MCT | AT5: COMPASS | AU5: KOMCA | AW5: MUST | AX5: SAMRO | AY5: AKM
B6: AKM-AUME | C6: Kobalt Paid By | D6: AKM | E6: SABAM | F6: SACEM | G6: GEMA | H6: SIAE | I6: BUMA | J6: STIM | K6: SPA | L6: SGAE | M6: STIM | N6: SUISA | O6: MCPS-PRS | P6: IDM | Q6: D-Version | R6: Schubert | S6: Blue Sun | T6: Dalia | U6: Pop Arabia | V6: Zeplin | W6: SOCAN | X6: ASCAP/BMI/SESAC/GMR | Y6: SADAIC | Z6: No Membership | AA6: ABRAMUS | AB6: SCD | AC6: SAYCO | AD6: Briana Music | AE6: SAYCE | AF6: SACM | AG6: No Membership | AH6: APDAYC | AI6: AGADU | AJ6: APRA-AMCOS | AK6: APRA-AMCOS | AL6: CASH | AM6: CASH | AO6: SMPJ | AP6: Indie Works | AQ6: COMPASS | AR6: COMPASS | AS6: COMPASS | AT6: COMPASS | AU6: EKKO | AW6: One Asia | AX6: SAMRO | AY6: SACEM
A7: BUMA-STEMRA | B7: BUMA-STEMRA | C7: Licensed By | D7: BUMA | E7: BUMA | F7: BUMA | G7: BUMA | H7: BUMA | I7: BUMA | J7: BUMA | K7: BUMA | L7: BUMA | M7: BUMA | N7: BUMA | O7: BUMA | P7: BUMA | Q7: BUMA | R7: BUMA | S7: RAO | T7: ACUM | U7: ESMAA | V7: MSG | W7: SOCAN | X7: ASCAP/BMI/SESAC/GMR | Y7: SADAIC | Z7: Latin Autor | AA7: ECAD | AB7: Latin Autor | AC7: Latin Autor | AD7: Latin Autor | AE7: Latin Autor | AF7: SACM | AG7: Latin Autor | AH7: Latin Autor | AI7: Latin Autor | AJ7: APRA-AMCOS | AK7: APRA-AMCOS | AL7: MCSC | AM7: APRA-AMCOS | AN7: APRA-AMCOS | AO7: APRA-AMCOS | AP7: APRA-AMCOS | AQ7: APRA-AMCOS | AR7: APRA-AMCOS | AS7: APRA-AMCOS | AT7: APRA-AMCOS | AU7: KOMCA | AV7: APRA-AMCOS | AW7: APRA-AMCOS | AX7: SAMRO | AY7: BUMA
B8: BUMA-STEMRA | C8: Licensor Pays | D8: BUMA | E8: BUMA | F8: BUMA | G8: BUMA | H8: BUMA | I8: BUMA | J8: BUMA | K8: BUMA | L8: BUMA | M8: BUMA | N8: BUMA | O8: BUMA | P8: BUMA | Q8: BUMA | R8: BUMA | S8: Blue Sun | T8: Dalia | U8: Pop Arabia | V8: Zeplin | W8: SOCAN | X8: ASCAP/BMI/SESAC/GMR | Y8: SADAIC | Z8: Latin Autor (Processed by BO) | AA8: ECAD | AB8: Latin Autor (Processed by BO) | AC8: Latin Autor (Processed by BO) | AD8: Latin Autor (Processed by BO) | AE8: Latin Autor (Processed by BO) | AF8: SACM | AG8: Latin Autor (Processed by BO) | AH8: Latin Autor (Processed by BO) | AI8: Latin Autor (Processed by BO) | AJ8: APRA-AMCOS | AK8: APRA-AMCOS | AL8: MCSC | AM8: BUMA | AN8: BUMA | AO8: BUMA | AP8: BUMA | AQ8: BUMA | AR8: BUMA | AS8: BUMA | AT8: BUMA | AU8: KOMCA | AV8: BUMA | AW8: BUMA | AX8: SAMRO | AY8: BUMA
B9: BUMA-STEMRA | C9: Kobalt Paid By | D9: AKM | E9: SABAM | F9: SACEM | G9: GEMA | H9: SIAE | I9: BUMA | J9: Nordic Sources | K9: SPA | L9: SGAE | M9: STIM | N9: SUISA | O9: MCPS-PRS | P9: IDM | Q9: D-Version | R9: Schubert | S9: Blue Sun | T9: Dalia | U9: Pop Arabia | V9: Zeplin | W9: SOCAN | X9: ASCAP/BMI/SESAC/GMR | Y9: SADAIC | Z9: No Membership | AA9: ABRAMUS | AB9: SCD | AC9: SAYCO | AD9: Briana Music | AE9: SAYCE | AF9: SACM | AG9: No Membership | AH9: APDAYC | AI9: AGADU | AJ9: APRA-AMCOS | AK9: APRA-AMCOS | AL9: CASH | AM9: CASH | AN9: Turnkey | AO9: SMPJ | AP9: Indie Works | AQ9: STIM | AR9: STIM | AS9: STIM | AT9: STIM | AU9: EKKO | AV9: PT Nadaku | AW9: One Asia | AX9: SAMRO | AY9: BUMA
A10: GEMA | B10: GEMA | C10: Licensed By | D10: ICE | E10: ICE | F10: ICE | G10: GEMA | H10: ICE | I10: ICE | J10: ICE | K10: ICE | L10: ICE | M10: ICE | N10: ICE | O10: ICE | P10: ICE | Q10: ICE | R10: ICE | S10: RAO | T10: ACUM | U10: ESMAA | V10: MSG | W10: SOCAN | X10: ASCAP/BMI/SESAC/GMR | Y10: SADAIC | Z10: Latin Autor | AA10: ECAD | AB10: SCD | AC10: SAYCO | AD10: Latin Autor | AE10: Latin Autor | AF10: SACM | AG10: Latin Autor | AH10: APDAYC | AI10: Latin Autor | AJ10: APRA-AMCOS | AK10: APRA-AMCOS | AL10: MCSC | AM10: CASH | AN10: IPRS | AO10: JASRAC | AP10: MACP | AQ10: FILSCAP | AR10: VCPMC | AS10: MCT | AT10: COMPASS | AU10: KOMCA | AV10: WAMI | AW10: MUST | AX10: SAMRO | AY10: ICE
B11: GEMA | C11: Licensor Pays | D11: AKM | E11: SABAM | F11: SACEM | G11: GEMA | H11: SIAE | I11: BUMA | J11: Nordic Sources | K11: SPA | L11: SGAE | M11: STIM | N11: SUISA | O11: MCPS-PRS | P11: HDS-ZAMP | Q11: GEMA | R11: ZAIKS | S11: Blue Sun | T11: Dalia | U11: Pop Arabia | V11: Zeplin | W11: SOCAN | X11: ASCAP/BMI/SESAC/GMR | Y11: SADAIC | Z11: Latin Autor (Processed by BO) | AA11: ECAD | AB11: SCD | AC11: SAYCO | AD11: Latin Autor (Processed by BO) | AE11: Latin Autor (Processed by BO) | AF11: SACM | AG11: Latin Autor (Processed by BO) | AH11: APDAYC | AI11: Latin Autor (Processed by BO) | AJ11: APRA-AMCOS | AK11: APRA-AMCOS | AL11: MCSC | AM11: CASH | AN11: IPRS | AO11: JASRAC | AP11: MACP | AQ11: FILSCAP | AR11: VCPMC | AS11: MCT | AT11: COMPASS | AU11: KOMCA | AV11: WAMI | AW11: MUST | AX11: SAMRO | AY11: GEMA
B12: GEMA | C12: Kobalt Paid By | D12: AKM | E12: SABAM | F12: SACEM | G12: GEMA | H12: SIAE | I12: BUMA | J12: Nordic Sources | K12: SPA | L12: SGAE | M12: STIM | N12: SUISA | O12: MCPS-PRS | P12: IDM | Q12: D-Version | R12: Schubert | S12: Blue Sun | T12: Dalia | U12: Pop Arabia | V12: Zeplin | W12: SOCAN | X12: ASCAP/BMI/SESAC/GMR | Y12: SADAIC | Z12: No Membership | AA12: ABRAMUS | AB12: SCD | AC12: SAYCO | AD12: Briana Music | AE12: SAYCE | AF12: SACM | AG12: No Membership | AH12: APDAYC | AI12: AGADU | AJ12: APRA-AMCOS | AK12: APRA-AMCOS | AL12: CASH | AM12: CASH | AN12: Turnkey | AO12: SMPJ | AP12: Indie Works | AQ12: COMPASS | AR12: COMPASS | AS12: COMPASS | AT12: COMPASS | AU12: EKKO | AV12: PT Nadaku | AW12: One Asia | AX12: SAMRO | AY12: GEMA
A13: SABAM | B13: SABAM | C13: Licensed By | D13: ICE | E13: ICE | F13: ICE | G13: ICE | H13: ICE | I13: ICE | J13: ICE | K13: ICE | L13: ICE | M13: ICE | N13: ICE | O13: ICE | P13: ICE | Q13: ICE | R13: ICE | S13: RAO | T13: ACUM | U13: ESMAA | V13: MSG | W13: SOCAN | X13: ASCAP/BMI/SESAC/GMR | Y13: SADAIC | Z13: Latin Autor | AA13: ECAD | AB13: Latin Autor | AC13: Latin Autor | AD13: Latin Autor | AE13: Latin Autor | AF13: SACM | AG13: Latin Autor | AH13: Latin Autor | AI13: Latin Autor | AJ13: APRA-AMCOS | AK13: APRA-AMCOS | AL13: MCSC | AM13: CASH | AN13: IPRS | AO13: JASRAC | AP13: MACP | AQ13: FILSCAP | AR13: VCPMC | AS13: MCT | AT13: COMPASS | AU13: KOMCA | AV13: WAMI | AW13: MUST | AX13: SAMRO | AY13: ICE
B14: SABAM | C14: Licensor Pays | D14: SABAM | E14: SABAM | F14: SABAM | G14: SABAM | H14: SABAM | I14: SABAM | J14: SABAM | K14: SABAM | L14: SABAM | M14: SABAM | N14: SABAM | O14: SABAM | P14: SABAM | Q14: SABAM | R14: SABAM | S14: Blue Sun | T14: Dalia | U14: Pop Arabia | V14: Zeplin | W14: SOCAN | X14: ASCAP/BMI/SESAC/GMR | Y14: SADAIC | Z14: Latin Autor (Processed by BO) | AA14: ECAD | AB14: Latin Autor (Processed by BO) | AC14: Latin Autor (Processed by BO) | AD14: Latin Autor (Processed by BO) | AE14: Latin Autor (Processed by BO) | AF14: SACM | AG14: Latin Autor (Processed by BO) | AH14: Latin Autor (Processed by BO) | AI14: Latin Autor (Processed by BO) | AJ14: APRA-AMCOS | AK14: APRA-AMCOS | AL14: MCSC | AM14: CASH | AN14: IPRS | AO14: JASRAC | AP14: MACP | AQ14: FILSCAP | AR14: VCPMC | AS14: MCT | AT14: COMPASS | AU14: KOMCA | AV14: WAMI | AW14: MUST | AX14: SAMRO | AY14: SABAM
B15: SABAM | C15: Kobalt Paid By | D15: AKM | E15: SABAM | F15: SACEM | G15: GEMA | H15: SIAE | I15: BUMA | J15: Nordic Sources | K15: SPA | L15: SGAE | M15: STIM | N15: SUISA | O15: MCPS-PRS | P15: IDM | Q15: D-Version | R15: Schubert | S15: Blue Sun | T15: Dalia | U15: Pop Arabia | V15: Zeplin | W15: SOCAN | X15: ASCAP/BMI/SESAC/GMR | Y15: SADAIC | Z15: No Membership | AA15: ABRAMUS | AB15: SCD | AC15: SAYCO | AD15: Briana Music | AE15: SAYCE | AF15: SACM | AG15: No Membership | AH15: APDAYC | AI15: AGADU | AJ15: APRA-AMCOS | AK15: APRA-AMCOS | AL15: CASH | AM15: CASH | AN15: Turnkey | AO15: SMPJ | AP15: Indie Works | AQ15: COMPASS | AR15: COMPASS | AS15: COMPASS | AT15: COMPASS | AU15: EKKO | AV15: PT Nadaku | AW15: One Asia | AX15: SAMRO | AY15: SACEM
A16: SACEM | B16: SACEM | C16: Licensed By | D16: SACEM | E16: SACEM | F16: SACEM | G16: SACEM | H16: SACEM | I16: SACEM | J16: SACEM | K16: SACEM | L16: SACEM | M16: SACEM | N16: SACEM | O16: SACEM | P16: SACEM | Q16: SACEM | R16: SACEM | S16: RAO | T16: ACUM | U16: ESMAA | V16: MSG | W16: SOCAN | X16: ASCAP/BMI/SESAC/GMR | Y16: SADAIC | Z16: Latin Autor | AA16: ECAD | AB16: Latin Autor | AC16: Latin Autor | AD16: Latin Autor | AE16: Latin Autor | AF16: SACM | AG16: Latin Autor | AH16: Latin Autor | AI16: Latin Autor | AJ16: APRA-AMCOS | AK16: APRA-AMCOS | AL16: QUERY SOURCE/ TERR OWNER | AM16: QUERY SOURCE/ TERR OWNER | AN16: QUERY SOURCE/ TERR OWNER | AO16: QUERY SOURCE/ TERR OWNER | AP16: QUERY SOURCE/ TERR OWNER | AQ16: QUERY SOURCE/ TERR OWNER | AR16: QUERY SOURCE/ TERR OWNER | AS16: QUERY SOURCE/ TERR OWNER | AT16: QUERY SOURCE/ TERR OWNER | AU16: QUERY SOURCE/ TERR OWNER | AV16: QUERY SOURCE/ TERR OWNER | AW16: QUERY SOURCE/ TERR OWNER | AX16: SAMRO | AY16: SACEM
B17: SACEM | C17: Licensor Pays | D17: SACEM | E17: SACEM | F17: SACEM | G17: SACEM | H17: SACEM | I17: SACEM | J17: SACEM | K17: SACEM | L17: SACEM | M17: SACEM | N17: SACEM | O17: SACEM | P17: SACEM | Q17: SACEM | R17: SACEM | S17: Blue Sun | T17: Dalia | U17: Pop Arabia | V17: Zeplin | W17: SOCAN | X17: ASCAP/BMI/SESAC/GMR | Y17: SADAIC | Z17: Latin Autor (Processed by BO) | AA17: ECAD | AB17: Latin Autor (Processed by BO) | AC17: Latin Autor (Processed by BO) | AD17: Latin Autor (Processed by BO) | AE17: Latin Autor (Processed by BO) | AF17: SACM | AG17: Latin Autor (Processed by BO) | AH17: Latin Autor (Processed by BO) | AI17: Latin Autor (Processed by BO) | AJ17: APRA-AMCOS | AK17: APRA-AMCOS | AL17: QUERY SOURCE/ TERR OWNER | AM17: QUERY SOURCE/ TERR OWNER | AN17: QUERY SOURCE/ TERR OWNER | AO17: QUERY SOURCE/ TERR OWNER | AP17: QUERY SOURCE/ TERR OWNER | AQ17: QUERY SOURCE/ TERR OWNER | AR17: QUERY SOURCE/ TERR OWNER | AS17: QUERY SOURCE/ TERR OWNER | AT17: QUERY SOURCE/ TERR OWNER | AU17: QUERY SOURCE/ TERR OWNER | AV17: QUERY SOURCE/ TERR OWNER | AW17: QUERY SOURCE/ TERR OWNER | AX17: SAMRO | AY17: SACEM
B18: SACEM | C18: Kobalt Paid By | D18: SACEM | E18: SACEM | F18: SACEM | G18: SACEM | H18: SACEM | I18: SACEM | J18: SACEM | K18: SACEM | L18: SACEM | M18: SACEM | N18: SACEM | O18: SACEM | P18: SACEM | Q18: SACEM | R18: SACEM | S18: Blue Sun | T18: Dalia | U18: Pop Arabia | V18: Zeplin | W18: SOCAN | X18: ASCAP/BMI/SESAC/GMR | Y18: SADAIC | Z18: No Membership | AA18: ABRAMUS | AB18: SCD | AC18: SAYCO | AD18: Briana Music | AE18: SAYCE | AF18: SACM | AG18: No Membership | AH18: APDAYC | AI18: AGADU | AJ18: APRA-AMCOS | AK18: APRA-AMCOS | AL18: QUERY SOURCE/ TERR OWNER | AM18: QUERY SOURCE/ TERR OWNER | AN18: QUERY SOURCE/ TERR OWNER | AO18: QUERY SOURCE/ TERR OWNER | AP18: QUERY SOURCE/ TERR OWNER | AQ18: QUERY SOURCE/ TERR OWNER | AR18: QUERY SOURCE/ TERR OWNER | AS18: QUERY SOURCE/ TERR OWNER | AT18: QUERY SOURCE/ TERR OWNER | AU18: QUERY SOURCE/ TERR OWNER | AV18: QUERY SOURCE/ TERR OWNER | AW18: QUERY SOURCE/ TERR OWNER | AX18: SAMRO | AY18: SACEM
A19: SGAE | B19: SGAE | C19: Licensed By | D19: AKM | E19: SABAM | F19: SACEM | G19: GEMA | H19: SIAE | I19: BUMA | J19: Nordic Sources | K19: SPA | L19: SGAE | M19: STIM | N19: SUISA | O19: MCPS-PRS | P19: HDS-ZAMP | Q19: AUTODIA | R19: ZAIKS | S19: RAO | T19: ACUM | U19: ESMAA | V19: MSG | W19: SOCAN | X19: ASCAP/BMI/SESAC/GMR | Y19: SADAIC | Z19: Latin Autor | AA19: ECAD | AB19: Latin Autor | AC19: Latin Autor | AD19: Latin Autor | AE19: Latin Autor | AF19: SACM | AG19: Latin Autor | AH19: Latin Autor | AI19: Latin Autor | AJ19: APRA-AMCOS | AK19: APRA-AMCOS | AL19: MCSC | AM19: CASH | AN19: IPRS | AO19: JASRAC | AP19: MACP | AQ19: FILSCAP | AR19: VCPMC | AS19: MCT | AT19: COMPASS | AU19: KOMCA | AV19: WAMI | AW19: MUST | AX19: SAMRO
B20: SGAE | C20: Licensor Pays | D20: AKM | E20: SABAM | F20: SACEM | G20: GEMA | H20: SIAE | I20: BUMA | J20: Nordic Sources | K20: SPA | L20: SGAE | M20: STIM | N20: SUISA | O20: MCPS-PRS | P20: IDM | Q20: D-Version | R20: Schubert | S20: Blue Sun | T20: Dalia | U20: Pop Arabia | V20: Zeplin | W20: SOCAN | X20: ASCAP/BMI/SESAC/GMR | Y20: SADAIC | Z20: Latin Autor (Processed by BO) | AA20: ECAD | AB20: Latin Autor (Processed by BO) | AC20: Latin Autor (Processed by BO) | AD20: Latin Autor (Processed by BO) | AE20: Latin Autor (Processed by BO) | AF20: SACM | AG20: Latin Autor (Processed by BO) | AH20: Latin Autor (Processed by BO) | AI20: Latin Autor (Processed by BO) | AJ20: APRA-AMCOS | AK20: APRA-AMCOS | AL20: MCSC | AM20: CASH | AN20: IPRS | AO20: JASRAC | AP20: MACP | AQ20: FILSCAP | AR20: VCPMC | AS20: MCT | AT20: COMPASS | AU20: KOMCA | AV20: WAMI | AW20: MUST | AX20: SAMRO
B21: SGAE | C21: Kobalt Paid By | D21: AKM | E21: SABAM | F21: SACEM | G21: GEMA | H21: SIAE | I21: BUMA | J21: Nordic Sources | K21: SPA | L21: SGAE | M21: STIM | N21: SUISA | O21: MCPS-PRS | P21: IDM | Q21: D-Version | R21: Schubert | S21: Blue Sun | T21: Dalia | U21: Pop Arabia | V21: Zeplin | W21: SOCAN | X21: ASCAP/BMI/SESAC/GMR | Y21: SADAIC | Z21: No Membership | AA21: ABRAMUS | AB21: SCD | AC21: SAYCO | AD21: Briana Music | AE21: SAYCE | AF21: SACM | AG21: No Membership | AH21: APDAYC | AI21: AGADU | AJ21: APRA-AMCOS | AK21: APRA-AMCOS | AL21: CASH | AM21: CASH | AN21: Turnkey | AO21: SMPJ | AP21: Indie Works | AQ21: COMPASS | AR21: COMPASS | AS21: COMPASS | AT21: COMPASS | AU21: EKKO | AV21: PT Nadaku | AW21: One Asia | AX21: SAMRO
A22: SIAE | B22: SIAE | C22: Licensed By | D22: AKM | E22: SABAM | F22: SACEM | G22: GEMA | H22: SIAE | I22: BUMA | J22: Nordic Sources | K22: SPA | L22: SGAE | M22: STIM | N22: SUISA | O22: MCPS-PRS | P22: QUERY SOURCE/ TERR OWNER | Q22: QUERY SOURCE/ TERR OWNER | R22: QUERY SOURCE/ TERR OWNER | S22: RAO | T22: ACUM | U22: ESMAA | V22: MSG | W22: SOCAN | X22: ASCAP/BMI/SESAC/GMR | Y22: SADAIC | Z22: Latin Autor | AA22: ECAD | AB22: Latin Autor | AC22: Latin Autor | AD22: Latin Autor | AE22: Latin Autor | AF22: SACM | AG22: Latin Autor | AH22: Latin Autor | AI22: Latin Autor | AJ22: APRA-AMCOS | AK22: APRA-AMCOS | AL22: MCSC | AM22: CASH | AN22: IPRS | AO22: JASRAC | AP22: MACP | AQ22: FILSCAP | AR22: VCPMC | AS22: MCT | AT22: COMPASS | AU22: KOMCA | AV22: WAMI | AW22: MUST | AX22: SAMRO | AY22: QUERY SOURCE/ TERR OWNER
B23: SIAE | C23: Licensor Pays | D23: AKM | E23: SABAM | F23: SACEM | G23: GEMA | H23: SIAE | I23: BUMA | J23: Nordic Sources | K23: SPA | L23: SGAE | M23: STIM | N23: SUISA | O23: MCPS-PRS | P23: QUERY SOURCE/ TERR OWNER | Q23: QUERY SOURCE/ TERR OWNER | R23: QUERY SOURCE/ TERR OWNER | S23: Blue Sun | T23: Dalia | U23: Pop Arabia | V23: Zeplin | W23: SOCAN | X23: ASCAP/BMI/SESAC/GMR | Y23: SADAIC | Z23: Latin Autor (Processed by BO) | AA23: ECAD | AB23: Latin Autor (Processed by BO) | AC23: Latin Autor (Processed by BO) | AD23: Latin Autor (Processed by BO) | AE23: Latin Autor (Processed by BO) | AF23: SACM | AG23: Latin Autor (Processed by BO) | AH23: Latin Autor (Processed by BO) | AI23: Latin Autor (Processed by BO) | AJ23: APRA-AMCOS | AK23: APRA-AMCOS | AL23: MCSC | AM23: CASH | AN23: IPRS | AO23: JASRAC | AP23: MACP | AQ23: FILSCAP | AR23: VCPMC | AS23: MCT | AT23: COMPASS | AU23: KOMCA | AV23: WAMI | AW23: MUST | AX23: SAMRO | AY23: QUERY SOURCE/ TERR OWNER
B24: SIAE | C24: Kobalt Paid By | D24: AKM | E24: SABAM | F24: SACEM | G24: GEMA | H24: SIAE | I24: BUMA | J24: Nordic Sources | K24: SPA | L24: SGAE | M24: STIM | N24: SUISA | O24: MCPS-PRS | P24: IDM | Q24: D-Version | R24: Schubert | S24: Blue Sun | T24: Dalia | U24: Pop Arabia | V24: Zeplin | W24: SOCAN | X24: ASCAP/BMI/SESAC/GMR | Y24: SADAIC | Z24: No Membership | AA24: ABRAMUS | AB24: SCD | AC24: SAYCO | AD24: Briana Music | AE24: SAYCE | AF24: SACM | AG24: No Membership | AH24: APDAYC | AI24: AGADU | AJ24: APRA-AMCOS | AK24: APRA-AMCOS | AL24: CASH | AM24: CASH | AN24: Turnkey | AO24: SMPJ | AP24: Indie Works | AQ24: COMPASS | AR24: COMPASS | AS24: COMPASS | AT24: COMPASS | AU24: EKKO | AV24: PT Nadaku | AW24: One Asia | AX24: SAMRO | AY24: QUERY SOURCE/ TERR OWNER
A25: SPA | B25: SPA | C25: Licensed By | D25: AKM | E25: SABAM | F25: SACEM | G25: GEMA | H25: SIAE | I25: BUMA | J25: Nordic Sources | K25: SPA | L25: SGAE | M25: STIM | N25: SUISA | O25: MCPS-PRS | P25: HDS-ZAMP | Q25: AUTODIA | R25: ZAIKS | S25: RAO | T25: ACUM | U25: ESMAA | V25: MSG | W25: SOCAN | X25: ASCAP/BMI/SESAC/GMR | Y25: SADAIC | Z25: Latin Autor | AA25: ABRAMUS | AB25: SCD | AC25: SAYCO | AD25: Latin Autor | AE25: Latin Autor | AF25: SACM | AG25: Latin Autor | AH25: APDAYC | AI25: Latin Autor | AJ25: APRA-AMCOS | AK25: APRA-AMCOS | AM25: CASH | AO25: JASRAC | AP25: MACP | AQ25: FILSCAP | AR25: VCPMC | AS25: MCT | AU25: KOMCA | AW25: MUST | AX25: SAMRO
B26: SPA | C26: Licensor Pays | D26: AKM | E26: SABAM | F26: SACEM | G26: GEMA | H26: SIAE | I26: BUMA | J26: Nordic Sources | K26: SPA | L26: SGAE | M26: STIM | N26: SUISA | O26: MCPS-PRS | P26: IDM | Q26: D-Version | R26: Schubert | S26: Blue Sun | T26: Dalia | U26: Pop Arabia | V26: Zeplin | W26: SOCAN | X26: ASCAP/BMI/SESAC/GMR | Y26: SADAIC | Z26: Latin Autor (Processed by BO) | AA26: ABRAMUS | AB26: SCD | AC26: SAYCO | AD26: Latin Autor (Processed by BO) | AE26: Latin Autor (Processed by BO) | AF26: SACM | AG26: Latin Autor (Processed by BO) | AH26: APDAYC | AI26: Latin Autor (Processed by BO) | AJ26: APRA-AMCOS | AK26: APRA-AMCOS | AM26: CASH | AO26: JASRAC | AP26: MACP | AQ26: FILSCAP | AR26: VCPMC | AS26: MCT | AU26: KOMCA | AW26: MUST | AX26: SAMRO
B27: SPA | C27: Kobalt Paid By | D27: AKM | E27: SABAM | F27: SACEM | G27: GEMA | H27: SIAE | I27: BUMA | J27: Nordic Sources | K27: SPA | L27: SGAE | M27: STIM | N27: SUISA | O27: MCPS-PRS | P27: IDM | Q27: D-Version | R27: Schubert | S27: Blue Sun | T27: Dalia | U27: Pop Arabia | V27: Zeplin | W27: SOCAN | X27: ASCAP/BMI/SESAC/GMR | Y27: SADAIC | Z27: No Membership | AA27: ABRAMUS | AB27: SCD | AC27: SAYCO | AD27: Briana Music | AE27: SAYCE | AF27: SACM | AG27: No Membership | AH27: APDAYC | AI27: AGADU | AJ27: APRA-AMCOS | AK27: APRA-AMCOS | AM27: CASH | AO27: SMPJ | AP27: Indie Works | AQ27: COMPASS | AR27: COMPASS | AS27: Compass | AU27: EKKO | AW27: One Asia | AX27: SAMRO
A28: STIM-NCB | B28: STIM-NCB | C28: Licensed By | D28: ICE | E28: ICE | F28: ICE | G28: ICE | H28: ICE | I28: ICE | J28: ICE | K28: ICE | L28: ICE | M28: ICE | N28: ICE | O28: ICE | P28: ICE | Q28: ICE | R28: ICE | S28: RAO | T28: ACUM | U28: ESMAA | V28: MSG | W28: SOCAN | X28: ASCAP/BMI/SESAC/GMR | Y28: SADAIC | Z28: Latin Autor | AA28: ECAD | AB28: Latin Autor | AC28: Latin Autor | AD28: Latin Autor | AE28: Latin Autor | AF28: SACM | AG28: Latin Autor | AH28: Latin Autor | AI28: Latin Autor | AJ28: APRA-AMCOS | AK28: APRA-AMCOS | AL28: APRA-AMCOS | AM28: APRA-AMCOS | AN28: APRA-AMCOS | AO28: APRA-AMCOS | AP28: APRA-AMCOS | AQ28: APRA-AMCOS | AR28: APRA-AMCOS | AS28: APRA-AMCOS | AT28: APRA-AMCOS | AU28: APRA-AMCOS | AV28: APRA-AMCOS | AW28: APRA-AMCOS | AX28: SAMRO | AY28: ICE
B29: STIM-NCB | C29: Licensor Pays | D29: STIM | E29: STIM | F29: STIM | G29: STIM | H29: STIM | I29: STIM | J29: STIM | K29: STIM | L29: STIM | M29: STIM | N29: STIM | O29: STIM | P29: STIM | Q29: STIM | R29: STIM | S29: Blue Sun | T29: Dalia | U29: Pop Arabia | V29: Zeplin | W29: SOCAN | X29: ASCAP/BMI/SESAC/GMR | Y29: SADAIC | Z29: Latin Autor (Processed by BO) | AA29: ECAD | AB29: Latin Autor (Processed by BO) | AC29: Latin Autor (Processed by BO) | AD29: Latin Autor (Processed by BO) | AE29: Latin Autor (Processed by BO) | AF29: SACM | AG29: Latin Autor (Processed by BO) | AH29: Latin Autor (Processed by BO) | AI29: Latin Autor (Processed by BO) | AJ29: APRA-AMCOS | AK29: APRA-AMCOS | AL29: STIM | AM29: STIM | AN29: STIM | AO29: STIM | AP29: STIM | AQ29: STIM | AR29: STIM | AS29: STIM | AT29: STIM | AU29: STIM | AV29: STIM | AW29: STIM | AX29: SAMRO | AY29: STIM
B30: STIM-NCB | C30: Kobalt Paid By | D30: STIM | E30: STIM | F30: STIM | G30: STIM | H30: STIM | I30: STIM | J30: STIM | K30: STIM | L30: STIM | M30: STIM | N30: STIM | O30: STIM | P30: IDM | Q30: D-Version | R30: Schubert | S30: Blue Sun | T30: Dalia | U30: Pop Arabia | V30: Zeplin | W30: SOCAN | X30: ASCAP/BMI/SESAC/GMR | Y30: SADAIC | Z30: No Membership | AA30: ABRAMUS | AB30: SCD | AC30: SAYCO | AD30: Briana Music | AE30: SAYCE | AF30: SACM | AG30: No Membership | AH30: APDAYC | AI30: AGADU | AJ30: APRA-AMCOS | AK30: APRA-AMCOS | AL30: STIM | AM30: STIM | AN30: Turnkey | AO30: SMPJ | AP30: Indie Works | AQ30: STIM | AR30: STIM | AS30: STIM | AT30: STIM | AU30: EKKO | AV30: PT Nadaku | AW30: One Asia | AX30: SAMRO | AY30: STIM
A31: SUISA | B31: SUISA | C31: Licensed By | D31: MINT / ICE | E31: MINT / ICE | F31: MINT / ICE | G31: MINT / ICE | H31: MINT / ICE | I31: MINT / ICE | J31: MINT / ICE | K31: MINT / ICE | L31: MINT / ICE | M31: MINT / ICE | N31: SUISA | O31: MINT | P31: MINT / ICE | Q31: MINT / ICE | R31: MINT / ICE | S31: RAO | T31: ACUM | U31: ESMAA | V31: MSG | W31: SOCAN | X31: ASCAP/BMI/SESAC/GMR | Y31: SADAIC | Z31: Latin Autor | AA31: ECAD | AB31: Latin Autor | AC31: Latin Autor | AD31: Latin Autor | AE31: Latin Autor | AF31: SACM | AG31: Latin Autor | AH31: APDAYC | AI31: AGADU | AJ31: APRA-AMCOS | AK31: APRA-AMCOS | AL31: MCSC | AM31: CASH | AN31: IPRS | AO31: JASRAC | AP31: MACP | AQ31: FILSCAP | AR31: VCPMC | AT31: COMPASS | AU31: KOMCA | AV31: WAMI | AW31: MUST | AX31: SAMRO
B32: SUISA | C32: Licensor Pays | D32: AKM | E32: SABAM | F32: SACEM | G32: GEMA | H32: SIAE | I32: BUMA | J32: STIM | K32: SPA | L32: SGAE | M32: STIM | N32: SUISA | O32: MCPS-PRS | P32: HDS ZAMP | Q32: AUTODIA | R32: ZAIKS | S32: Blue Sun | T32: Dalia | U32: Pop Arabia | V32: Zeplin | W32: SOCAN | X32: ASCAP/BMI/SESAC/GMR | Y32: SADAIC | Z32: Latin Autor (Processed by BO) | AA32: ECAD | AB32: Latin Autor (Processed by BO) | AC32: Latin Autor (Processed by BO) | AD32: Latin Autor (Processed by BO) | AE32: Latin Autor (Processed by BO) | AF32: SACM | AG32: Latin Autor (Processed by BO) | AH32: APDAYC | AI32: Latin Autor (Processed by BO) | AJ32: APRA-AMCOS | AK32: APRA-AMCOS | AL32: MCSC | AM32: CASH | AN32: IPRS | AO32: JASRAC | AP32: MACP | AQ32: FILSCAP | AR32: VCPMC | AT32: COMPASS | AU32: KOMCA | AV32: WAMI | AW32: MUST | AX32: SAMRO
B33: SUISA | C33: Kobalt Paid By | D33: AKM | E33: SABAM | F33: SACEM | G33: GEMA | H33: SIAE | I33: BUMA | J33: STIM | K33: SPA | L33: SGAE | M33: STIM | N33: SUISA | O33: MCPS-PRS | P33: IDM | Q33: D-Version | R33: Schubert | S33: Blue Sun | T33: Dalia | U33: Pop Arabia | V33: Zeplin | W33: SOCAN | X33: ASCAP/BMI/SESAC/GMR | Y33: SADAIC | Z33: No Membership | AA33: ABRAMUS | AB33: SCD | AC33: SAYCO | AD33: Briana Music | AE33: SAYCE | AF33: SACM | AG33: No Membership | AH33: APDAYC | AI33: AGADU | AJ33: APRA-AMCOS | AK33: APRA-AMCOS | AL33: CASH | AM33: CASH | AN33: Turnkey | AO33: SMPJ | AP33: Indie Works | AQ33: COMPASS | AR33: COMPASS | AT33: COMPASS | AU33: EKKO | AV33: PT Nadaku | AW33: One Asia | AX33: SAMRO
A34: Anglo-Am Rep
A35: AMRA | B35: AMRA | C35: Licensed By | D35: AMRA | E35: AMRA | F35: AMRA | G35: AMRA | H35: AMRA | I35: AMRA | J35: AMRA | K35: AMRA | L35: AMRA | M35: AMRA | N35: AMRA | O35: AMRA | P35: AMRA | Q35: AMRA | R35: AMRA | S35: AMRA | T35: AMRA | U35: AMRA | V35: AMRA | W35: SOCAN | X35: ASCAP/BMI/SESAC/GMR | Y35: SADAIC | Z35: Latin Autor | AA35: ECAD | AB35: Latin Autor | AC35: Latin Autor | AD35: Latin Autor | AE35: Latin Autor | AF35: SACM | AG35: Latin Autor | AH35: Latin Autor | AI35: Latin Autor | AJ35: AMRA | AK35: AMRA | AL35: AMRA | AM35: AMRA | AN35: AMRA | AO35: AMRA | AP35: AMRA | AQ35: AMRA | AR35: AMRA | AS35: AMRA | AT35: AMRA | AU35: KOMCA | AV35: AMRA | AW35: AMRA | AX35: AMRA | AY35: AMRA
B36: AMRA | C36: Licensor Pays | D36: AMRA | E36: AMRA | F36: AMRA | G36: AMRA | H36: AMRA | I36: AMRA | J36: AMRA | K36: AMRA | L36: AMRA | M36: AMRA | N36: AMRA | O36: AMRA | P36: AMRA | Q36: AMRA | R36: AMRA | S36: AMRA | T36: AMRA | U36: AMRA | V36: AMRA | W36: SOCAN | X36: ASCAP/BMI/SESAC/GMR | Y36: SADAIC | Z36: Latin Autor (Processed by BO) | AA36: ECAD | AB36: Latin Autor (Processed by BO) | AC36: Latin Autor (Processed by BO) | AD36: Latin Autor (Processed by BO) | AE36: Latin Autor (Processed by BO) | AF36: SACM | AG36: Latin Autor (Processed by BO) | AH36: Latin Autor (Processed by BO) | AI36: Latin Autor (Processed by BO) | AJ36: AMRA | AK36: AMRA | AL36: AMRA | AM36: AMRA | AN36: AMRA | AO36: AMRA | AP36: AMRA | AQ36: AMRA | AR36: AMRA | AS36: AMRA | AT36: AMRA | AU36: KOMCA | AV36: AMRA | AW36: AMRA | AX36: AMRA | AY36: AMRA
B37: AMRA | C37: Kobalt Paid By | D37: AMRA | E37: AMRA | F37: AMRA | G37: AMRA | H37: AMRA | I37: AMRA | J37: AMRA | K37: AMRA | L37: AMRA | M37: AMRA | N37: AMRA | O37: AMRA | P37: AMRA | Q37: AMRA | R37: AMRA | S37: AMRA | T37: AMRA | U37: AMRA | V37: AMRA | W37: SOCAN | X37: ASCAP/BMI/SESAC/GMR | Y37: SADAIC | Z37: No Membership | AA37: ABRAMUS | AB37: SCD | AC37: SAYCO | AD37: Briana Music | AE37: SAYCE | AF37: SACM | AG37: No Membership | AH37: APDAYC | AI37: AGADU | AJ37: AMRA | AK37: AMRA | AL37: AMRA | AM37: AMRA | AN37: AMRA | AO37: AMRA | AP37: AMRA | AQ37: AMRA | AR37: AMRA | AS37: AMRA | AT37: AMRA | AU37: EKKO | AV37: AMRA | AW37: AMRA | AX37: AMRA | AY37: AMRA
A38: APRA-AMCOS | B38: APRA-AMCOS | C38: Licensed By | D38: AMRA | E38: AMRA | F38: AMRA | G38: AMRA | H38: AMRA | I38: AMRA | J38: AMRA | K38: AMRA | L38: AMRA | M38: AMRA | N38: AMRA | O38: AMRA | P38: AMRA | Q38: AMRA | R38: AMRA | S38: AMRA | T38: AMRA | U38: AMRA | V38: AMRA | W38: SOCAN | X38: ASCAP/BMI/SESAC/GMR | Y38: SADAIC | Z38: Latin Autor | AA38: ECAD | AB38: Latin Autor | AC38: Latin Autor | AD38: Latin Autor | AE38: Latin Autor | AF38: SACM | AG38: Latin Autor | AH38: Latin Autor | AI38: Latin Autor | AJ38: APRA-AMCOS | AK38: APRA-AMCOS | AL38: AMRA | AM38: AMRA | AN38: AMRA | AO38: AMRA | AP38: AMRA | AQ38: AMRA | AR38: AMRA | AS38: AMRA | AT38: AMRA | AU38: KOMCA | AV38: AMRA | AW38: AMRA | AX38: AMRA | AY38: AMRA
B39: APRA-AMCOS | C39: Licensor Pays | D39: AMRA | E39: AMRA | F39: AMRA | G39: AMRA | H39: AMRA | I39: AMRA | J39: AMRA | K39: AMRA | L39: AMRA | M39: AMRA | N39: AMRA | O39: AMRA | P39: AMRA | Q39: AMRA | R39: AMRA | S39: AMRA | T39: AMRA | U39: AMRA | V39: AMRA | W39: SOCAN | X39: ASCAP/BMI/SESAC/GMR | Y39: SADAIC | Z39: Latin Autor (Processed by BO) | AA39: ECAD | AB39: Latin Autor (Processed by BO) | AC39: Latin Autor (Processed by BO) | AD39: Latin Autor (Processed by BO) | AE39: Latin Autor (Processed by BO) | AF39: SACM | AG39: Latin Autor (Processed by BO) | AH39: Latin Autor (Processed by BO) | AI39: Latin Autor (Processed by BO) | AJ39: APRA-AMCOS | AK39: APRA-AMCOS | AL39: AMRA | AM39: AMRA | AN39: AMRA | AO39: AMRA | AP39: AMRA | AQ39: AMRA | AR39: AMRA | AS39: AMRA | AT39: AMRA | AU39: KOMCA | AV39: AMRA | AW39: AMRA | AX39: AMRA | AY39: AMRA
B40: APRA-AMCOS | C40: Kobalt Paid By | D40: AMRA | E40: AMRA | F40: AMRA | G40: AMRA | H40: AMRA | I40: AMRA | J40: AMRA | K40: AMRA | L40: AMRA | M40: AMRA | N40: AMRA | O40: AMRA | P40: AMRA | Q40: AMRA | R40: AMRA | S40: AMRA | T40: AMRA | U40: AMRA | V40: AMRA | W40: SOCAN | X40: ASCAP/BMI/SESAC/GMR | Y40: SADAIC | Z40: No Membership | AA40: ABRAMUS | AB40: SCD | AC40: SAYCO | AD40: Briana Music | AE40: SAYCE | AF40: SACM | AG40: No Membership | AH40: APDAYC | AI40: AGADU | AJ40: APRA-AMCOS | AK40: APRA-AMCOS | AL40: AMRA | AM40: AMRA | AN40: AMRA | AO40: AMRA | AP40: AMRA | AQ40: AMRA | AR40: AMRA | AS40: AMRA | AT40: AMRA | AU40: EKKO | AV40: AMRA | AW40: AMRA | AX40: AMRA | AY40: AMRA
...

Sheet Matrix - MECH
A1: Licensed By: How our pub share is licensed Licensor Pays: First society income is paid to Kobalt Paid By: Pub share payment made to Kobalt | D1: MECHANICAL INCOME - NOT INCLUDED IN DL
D2: EUROPE | W2: US / Canada | Y2: Latin America | AJ2: Australasia | AL2: Asia | AX2: Africa
A3: BIEM Rep (Example: 1 Writer -> Kobalt) | B3: SOCIETY | D3: Austria | E3: Belgium | F3: France | G3: Germany | H3: Italy | I3: Netherlands | J3: Nordics Finland / Norway / Iceland, etc) | K3: Portugal | L3: Spain | M3: Sweden | N3: Switzerland | O3: United Kingdom | P3: Croatia | Q3: Greece | R3: Poland | S3: Russia | T3: Israel | U3: UAE | V3: Turkey | W3: Canada | X3: United States | Y3: Argentina | Z3: Bolivia | AA3: Brazil | AB3: Chile | AC3: Colombia | AD3: Costa Rica | AE3: Ecuador | AF3: Mexico | AG3: Paraguay | AH3: Peru | AI3: Uruguay | AJ3: Australia | AK3: New Zealand | AL3: China | AM3: HongKong | AN3: India | AO3: Japan | AP3: Malaysia | AQ3: Philippines | AR3: Vietnam | AS3: Thailand | AT3: Singapore | AU3: South Korea | AV3: Indonesia | AW3: Taiwan | AX3: South Africa | AY3: North Africa
A4: AKM-AUME | B4: AKM-AUME | C4: Licensed By | D4: ICE | E4: ICE | F4: ICE | G4: ICE | H4: ICE | I4: ICE | J4: ICE | K4: ICE | L4: ICE | M4: ICE | N4: ICE | O4: ICE | P4: ICE | Q4: ICE | R4: ICE | S4: RAO | T4: ACUM | U4: ESMAA | V4: MSG | W4: CMRRA | X4: MLC | Y4: SADAIC | Z4: Latin Autor | AA4: ABRAMUS | AB4: Latin Autor | AC4: Latin Autor | AD4: Latin Autor | AE4: Latin Autor | AF4: SACM | AG4: Latin Autor | AH4: Latin Autor | AI4: Latin Autor | AJ4: APRA-AMCOS | AK4: APRA-AMCOS | AL4: MCSC | AM4: CASH | AO4: JASRAC | AP4: MCPS | AS4: COMPASS | AT4: MCPS | AX4: CAPASSO | AY4: ICE
B5: AKM-AUME | C5: Licensor Pays | D5: AUME | E5: SABAM | F5: SACEM | G5: GEMA | H5: SIAE | I5: BUMA | J5: STIM | K5: SGAE | L5: SGAE | M5: STIM | N5: SUISA | O5: MCPS-PRS | P5: HDS-ZAMP | Q5: AUME | R5: AUME | S5: Blue Sun | T5: Dalia | U5: Pop Arabia | V5: Zeplin | W5: CMRRA | X5: MLC | Y5: SADAIC | Z5: Latin Autor (Processed by BO) | AA5: ABRAMUS | AB5: Latin Autor (Processed by BO) | AC5: Latin Autor (Processed by BO) | AD5: Latin Autor (Processed by BO) | AE5: Latin Autor (Processed by BO) | AF5: SACM | AG5: Latin Autor (Processed by BO) | AH5: Latin Autor (Processed by BO) | AI5: Latin Autor (Processed by BO) | AJ5: APRA-AMCOS | AK5: APRA-AMCOS | AL5: MCSC | AM5: CASH | AO5: JASRAC | AP5: AMRA | AS5: COMPASS | AT5: AMRA | AX5: CAPASSO | AY5: SACEM
B6: AKM-AUME | C6: Kobalt Paid By | D6: AUME | E6: SABAM | F6: SACEM | G6: GEMA | H6: SIAE | I6: BUMA | J6: STIM | K6: SGAE | L6: SGAE | M6: STIM | N6: SUISA | O6: MCPS-PRS | P6: IDM | Q6: D-Version | R6: Schubert | S6: Blue Sun | T6: Dalia | U6: Pop Arabia | V6: Zeplin | W6: CMRRA | X6: MLC | Y6: SADAIC | Z6: No Membership | AA6: ABRAMUS | AB6: Latin Autor | AC6: Latin Autor | AD6: Latin Autor | AE6: Latin Autor | AF6: SACM | AG6: No Membership | AH6: Latin Autor | AI6: Latin Autor | AJ6: APRA-AMCOS | AK6: APRA-AMCOS | AL6: CASH | AM6: CASH | AO6: SMPJ | AP6: AMRA | AS6: COMPASS | AT6: AMRA | AX6: CAPASSO | AY6: SACEM
A7: BUMA-STEMRA | B7: BUMA-STEMRA | C7: Licensed By | D7: STEMRA | E7: STEMRA | F7: STEMRA | G7: STEMRA | H7: STEMRA | I7: STEMRA | J7: STEMRA | K7: STEMRA | L7: STEMRA | M7: STEMRA | N7: STEMRA | O7: STEMRA | P7: STEMRA | Q7: STEMRA | R7: STEMRA | S7: RAO | T7: ACUM | U7: ESMAA | V7: MSG | W7: CMRRA | X7: MLC | Y7: SADAIC | Z7: Latin Autor | AA7: ABRAMUS | AB7: Latin Autor | AC7: Latin Autor | AD7: Latin Autor | AE7: Latin Autor | AF7: SACM | AG7: Latin Autor | AH7: Latin Autor | AI7: Latin Autor | AJ7: APRA-AMCOS | AK7: APRA-AMCOS | AL7: QUERY SOURCE/ TERR OWNER | AM7: APRA-AMCOS | AN7: APRA-AMCOS | AO7: APRA-AMCOS | AP7: APRA-AMCOS | AQ7: APRA-AMCOS | AR7: APRA-AMCOS | AS7: APRA-AMCOS | AT7: APRA-AMCOS | AU7: KOMCA | AV7: APRA-AMCOS | AW7: APRA-AMCOS | AX7: CAPASSO | AY7: STEMRA
B8: BUMA-STEMRA | C8: Licensor Pays | D8: STEMRA | E8: STEMRA | F8: STEMRA | G8: STEMRA | H8: STEMRA | I8: STEMRA | J8: STEMRA | K8: STEMRA | L8: STEMRA | M8: STEMRA | N8: STEMRA | O8: STEMRA | P8: STEMRA | Q8: STEMRA | R8: STEMRA | S8: Blue Sun | T8: Dalia | U8: Pop Arabia | V8: Zeplin | W8: CMRRA | X8: MLC | Y8: SADAIC | Z8: Latin Autor (Processed by BO) | AA8: ABRAMUS | AB8: Latin Autor (Processed by BO) | AC8: Latin Autor (Processed by BO) | AD8: Latin Autor (Processed by BO) | AE8: Latin Autor (Processed by BO) | AF8: SACM | AG8: Latin Autor (Processed by BO) | AH8: Latin Autor (Processed by BO) | AI8: Latin Autor (Processed by BO) | AJ8: APRA-AMCOS | AK8: APRA-AMCOS | AL8: QUERY SOURCE/ TERR OWNER | AM8: STEMRA | AN8: STEMRA | AO8: STEMRA | AP8: STEMRA | AQ8: STEMRA | AR8: STEMRA | AS8: STEMRA | AT8: STEMRA | AU8: KOMCA | AV8: STEMRA | AW8: STEMRA | AX8: CAPASSO | AY8: STEMRA
B9: BUMA-STEMRA | C9: Kobalt Paid By | D9: AUME | E9: SABAM | F9: SACEM | G9: GEMA | H9: SIAE | I9: BUMA | J9: STIM | K9: SPA | L9: SGAE | M9: STIM | N9: SUISA | O9: MCPS-PRS | P9: IDM | Q9: D-Version | R9: Schubert | S9: Blue Sun | T9: Dalia | U9: Pop Arabia | V9: Zeplin | W9: AMRA | X9: MLC | Y9: SADAIC | Z9: No Membership | AA9: ABRAMUS | AB9: Latin Autor | AC9: Latin Autor | AD9: Latin Autor | AE9: Latin Autor | AF9: SACM | AG9: No Membership | AH9: Latin Autor | AI9: Latin Autor | AJ9: APRA-AMCOS | AK9: APRA-AMCOS | AL9: QUERY SOURCE/ TERR OWNER | AM9: CASH | AN9: Turnkey | AO9: SMPJ | AP9: Indie Works | AQ9: STIM | AR9: STIM | AS9: STIM | AT9: STIM | AU9: EKKO | AV9: PT Nadaku | AW9: One Asia | AX9: CAPASSO | AY9: SACEM
A10: GEMA | B10: GEMA | C10: Licensed By | D10: ICE | E10: ICE | F10: ICE | G10: GEMA | H10: ICE | I10: ICE | J10: ICE | K10: ICE | L10: ICE | M10: ICE | N10: ICE | O10: ICE | P10: ICE | Q10: ICE | R10: ICE | S10: RAO | T10: ACUM | U10: ESMAA | V10: MSG | W10: CMRRA | X10: MLC | Y10: SADAIC | Z10: Latin Autor | AA10: ABRAMUS | AB10: Latin Autor | AC10: Latin Autor | AD10: Latin Autor | AE10: Latin Autor | AF10: SACM | AG10: Latin Autor | AH10: Latin Autor | AI10: Latin Autor | AJ10: APRA-AMCOS | AK10: APRA-AMCOS | AL10: MCSC | AM10: CASH | AN10: IPRS | AO10: JASRAC | AP10: MACP | AQ10: COMPASS | AR10: COMPASS | AS10: COMPASS | AT10: COMPASS | AU10: KOMCA | AV10: WAMI | AW10: MUST | AX10: CAPASSO | AY10: ICE
B11: GEMA | C11: Licensor Pays | D11: AUME | E11: SABAM | F11: SACEM | G11: GEMA | H11: SIAE | I11: BUMA | J11: Nordic Sources | K11: SPA | L11: SGAE | M11: STIM | N11: SUISA | O11: MCPS-PRS | P11: HDS-ZAMP | Q11: GEMA | R11: GEMA | S11: Blue Sun | T11: Dalia | U11: Pop Arabia | V11: Zeplin | W11: CMRRA | X11: MLC | Y11: SADAIC | Z11: Latin Autor (Processed by BO) | AA11: ABRAMUS | AB11: Latin Autor (Processed by BO) | AC11: Latin Autor (Processed by BO) | AD11: Latin Autor (Processed by BO) | AE11: Latin Autor (Processed by BO) | AF11: SACM | AG11: Latin Autor (Processed by BO) | AH11: Latin Autor (Processed by BO) | AI11: Latin Autor (Processed by BO) | AJ11: APRA-AMCOS | AK11: APRA-AMCOS | AL11: MCSC | AM11: CASH | AN11: IPRS | AO11: JASRAC | AP11: MACP | AQ11: COMPASS | AR11: COMPASS | AS11: COMPASS | AT11: COMPASS | AU11: KOMCA | AV11: WAMI | AW11: MUST | AX11: CAPASSO | AY11: GEMA
B12: GEMA | C12: Kobalt Paid By | D12: AUME | E12: SABAM | F12: SACEM | G12: GEMA | H12: SIAE | I12: BUMA | J12: Nordic Sources | K12: SPA | L12: SGAE | M12: STIM | N12: SUISA | O12: MCPS-PRS | P12: IDM | Q12: D-Version | R12: Schubert | S12: Blue Sun | T12: Dalia | U12: Pop Arabia | V12: Zeplin | W12: CMRRA | X12: MLC | Y12: SADAIC | Z12: No Membership | AA12: ABRAMUS | AB12: Latin Autor | AC12: Latin Autor | AD12: Latin Autor | AE12: Latin Autor | AF12: SACM | AG12: No Membership | AH12: Latin Autor | AI12: Latin Autor | AJ12: APRA-AMCOS | AK12: APRA-AMCOS | AL12: CASH | AM12: CASH | AN12: Turnkey | AO12: SMPJ | AP12: Indie Works | AQ12: COMPASS | AR12: COMPASS | AS12: COMPASS | AT12: COMPASS | AU12: EKKO | AV12: PT Nadaku | AW12: One Asia | AX12: CAPASSO | AY12: GEMA
A13: SABAM | B13: SABAM | C13: Licensed By | D13: ICE | E13: ICE | F13: ICE | G13: ICE | H13: ICE | I13: ICE | J13: ICE | K13: ICE | L13: ICE | M13: ICE | N13: ICE | O13: ICE | P13: ICE | Q13: ICE | R13: ICE | S13: RAO | T13: ACUM | U13: ESMAA | V13: MSG | W13: CMRRA | X13: MLC | Y13: SADAIC | Z13: Latin Autor | AA13: ABRAMUS | AB13: Latin Autor | AC13: Latin Autor | AD13: Latin Autor | AE13: Latin Autor | AF13: SACM | AG13: Latin Autor | AH13: Latin Autor | AI13: Latin Autor | AJ13: APRA-AMCOS | AK13: APRA-AMCOS | AL13: MCSC | AM13: CASH | AN13: QUERY SOURCE/ TERR OWNER | AO13: JASRAC | AP13: MACP | AQ13: FILSCAP | AR13: VCPMC | AS13: QUERY SOURCE/ TERR OWNER | AT13: COMPASS | AU13: KOMCA | AV13: QUERY SOURCE/ TERR OWNER | AW13: MUST | AX13: CAPASSO | AY13: ICE
B14: SABAM | C14: Licensor Pays | D14: SABAM | E14: SABAM | F14: SABAM | G14: SABAM | H14: SABAM | I14: SABAM | J14: SABAM | K14: SABAM | L14: SABAM | M14: SABAM | N14: SABAM | O14: SABAM | P14: SABAM | Q14: SABAM | R14: SABAM | S14: Blue Sun | T14: Dalia | U14: Pop Arabia | V14: Zeplin | W14: CMRRA | X14: MLC | Y14: SADAIC | Z14: Latin Autor (Processed by BO) | AA14: ABRAMUS | AB14: Latin Autor (Processed by BO) | AC14: Latin Autor (Processed by BO) | AD14: Latin Autor (Processed by BO) | AE14: Latin Autor (Processed by BO) | AF14: SACM | AG14: Latin Autor (Processed by BO) | AH14: Latin Autor (Processed by BO) | AI14: Latin Autor (Processed by BO) | AJ14: APRA-AMCOS | AK14: APRA-AMCOS | AL14: MCSC | AM14: CASH | AN14: QUERY SOURCE/ TERR OWNER | AO14: JASRAC | AP14: MACP | AQ14: FILSCAP | AR14: VCPMC | AS14: QUERY SOURCE/ TERR OWNER | AT14: COMPASS | AU14: KOMCA | AV14: QUERY SOURCE/ TERR OWNER | AW14: MUST | AX14: CAPASSO | AY14: SABAM
B15: SABAM | C15: Kobalt Paid By | D15: AUME | E15: SABAM | F15: SACEM | G15: GEMA | H15: SIAE | I15: BUMA | J15: STIM | K15: SPA | L15: SGAE | M15: STIM | N15: SUISA | O15: MCPS-PRS | P15: IDM | Q15: D-Version | R15: Schubert | S15: Blue Sun | T15: Dalia | U15: Pop Arabia | V15: Zeplin | W15: CMRRA | X15: MLC | Y15: SADAIC | Z15: No Membership | AA15: ABRAMUS | AB15: Latin Autor | AC15: Latin Autor | AD15: Latin Autor | AE15: Latin Autor | AF15: SACM | AG15: No Membership | AH15: Latin Autor | AI15: Latin Autor | AJ15: APRA-AMCOS | AK15: APRA-AMCOS | AL15: CASH | AM15: CASH | AN15: QUERY SOURCE/ TERR OWNER | AO15: SMPJ | AP15: Indie Works | AQ15: COMPASS | AR15: COMPASS | AS15: QUERY SOURCE/ TERR OWNER | AT15: COMPASS | AU15: EKKO | AV15: QUERY SOURCE/ TERR OWNER | AW15: One Asia | AX15: CAPASSO | AY15: SACEM
A16: SACEM | B16: SACEM | C16: Licensed By | D16: SACEM | E16: SACEM | F16: SACEM | G16: SACEM | H16: SACEM | I16: SACEM | J16: SACEM | K16: SACEM | L16: SACEM | M16: SACEM | N16: SACEM | O16: SACEM | P16: SACEM | Q16: SACEM | R16: SACEM | S16: RAO | T16: ACUM | U16: ESMAA | V16: MSG | W16: CMRRA | X16: MLC | Y16: SADAIC | Z16: Latin Autor | AA16: ABRAMUS | AB16: Latin Autor | AC16: Latin Autor | AD16: Latin Autor | AE16: Latin Autor | AF16: SACM | AG16: Latin Autor | AH16: Latin Autor | AI16: Latin Autor | AJ16: APRA-AMCOS | AK16: APRA-AMCOS | AL16: QUERY SOURCE/ TERR OWNER | AM16: QUERY SOURCE/ TERR OWNER | AN16: QUERY SOURCE/ TERR OWNER | AO16: QUERY SOURCE/ TERR OWNER | AP16: QUERY SOURCE/ TERR OWNER | AQ16: QUERY SOURCE/ TERR OWNER | AR16: QUERY SOURCE/ TERR OWNER | AS16: QUERY SOURCE/ TERR OWNER | AT16: QUERY SOURCE/ TERR OWNER | AU16: KOMCA | AV16: QUERY SOURCE/ TERR OWNER | AW16: QUERY SOURCE/ TERR OWNER | AX16: CAPASSO | AY16: SACEM
B17: SACEM | C17: Licensor Pays | D17: SACEM | E17: SACEM | F17: SACEM | G17: SACEM | H17: SACEM | I17: SACEM | J17: SACEM | K17: SACEM | L17: SACEM | M17: SACEM | N17: SACEM | O17: SACEM | P17: SACEM | Q17: SACEM | R17: SACEM | S17: Blue Sun | T17: Dalia | U17: Pop Arabia | V17: Zeplin | W17: CMRRA | X17: MLC | Y17: SADAIC | Z17: Latin Autor (Processed by BO) | AA17: ABRAMUS | AB17: Latin Autor (Processed by BO) | AC17: Latin Autor (Processed by BO) | AD17: Latin Autor (Processed by BO) | AE17: Latin Autor (Processed by BO) | AF17: SACM | AG17: Latin Autor (Processed by BO) | AH17: Latin Autor (Processed by BO) | AI17: Latin Autor (Processed by BO) | AJ17: APRA-AMCOS | AK17: APRA-AMCOS | AL17: QUERY SOURCE/ TERR OWNER | AM17: QUERY SOURCE/ TERR OWNER | AN17: QUERY SOURCE/ TERR OWNER | AO17: QUERY SOURCE/ TERR OWNER | AP17: QUERY SOURCE/ TERR OWNER | AQ17: QUERY SOURCE/ TERR OWNER | AR17: QUERY SOURCE/ TERR OWNER | AS17: QUERY SOURCE/ TERR OWNER | AT17: QUERY SOURCE/ TERR OWNER | AU17: KOMCA | AV17: QUERY SOURCE/ TERR OWNER | AW17: QUERY SOURCE/ TERR OWNER | AX17: CAPASSO | AY17: SACEM
B18: SACEM | C18: Kobalt Paid By | D18: SACEM | E18: SACEM | F18: SACEM | G18: SACEM | H18: SACEM | I18: SACEM | J18: SACEM | K18: SACEM | L18: SACEM | M18: SACEM | N18: SACEM | O18: SACEM | P18: SACEM | Q18: SACEM | R18: SACEM | S18: Blue Sun | T18: Dalia | U18: Pop Arabia | V18: Zeplin | W18: CMRRA | X18: MLC | Y18: SADAIC | Z18: No Membership | AA18: ABRAMUS | AB18: Latin Autor | AC18: Latin Autor | AD18: Latin Autor | AE18: Latin Autor | AF18: SACM | AG18: No Membership | AH18: Latin Autor | AI18: Latin Autor | AJ18: APRA-AMCOS | AK18: APRA-AMCOS | AL18: QUERY SOURCE/ TERR OWNER | AM18: QUERY SOURCE/ TERR OWNER | AN18: QUERY SOURCE/ TERR OWNER | AO18: QUERY SOURCE/ TERR OWNER | AP18: QUERY SOURCE/ TERR OWNER | AQ18: QUERY SOURCE/ TERR OWNER | AR18: QUERY SOURCE/ TERR OWNER | AS18: QUERY SOURCE/ TERR OWNER | AT18: QUERY SOURCE/ TERR OWNER | AU18: EKKO | AV18: QUERY SOURCE/ TERR OWNER | AW18: QUERY SOURCE/ TERR OWNER | AX18: CAPASSO | AY18: SACEM
A19: SGAE | B19: SGAE | C19: Licensed By | D19: AUME | E19: SABAM | F19: SACEM | G19: GEMA | H19: SIAE | I19: BUMA | J19: Nordic Sources | K19: SPA | L19: SGAE | M19: STIM | N19: SUISA | O19: MCPS-PRS | P19: HDS-ZAMP | Q19: AUTODIA | R19: ZAIKS | S19: RAO | T19: ACUM | U19: ESMAA | V19: MSG | W19: CMRRA | X19: MLC | Y19: SADAIC | Z19: Latin Autor | AA19: ABRAMUS | AB19: Latin Autor | AC19: Latin Autor | AD19: Latin Autor | AE19: Latin Autor | AF19: SACM | AG19: Latin Autor | AH19: Latin Autor | AI19: Latin Autor | AJ19: APRA-AMCOS | AK19: APRA-AMCOS | AL19: MCSC | AM19: CASH | AN19: IPRS | AO19: JASRAC | AP19: MACP | AQ19: FILSCAP | AR19: VCPMC | AS19: MCT | AT19: COMPASS | AU19: KOMCA | AX19: CAPASSO
B20: SGAE | C20: Licensor Pays | D20: AUME | E20: SABAM | F20: SACEM | G20: GEMA | H20: SIAE | I20: BUMA | J20: Nordic Sources | K20: SPA | L20: SGAE | M20: STIM | N20: SUISA | O20: MCPS-PRS | P20: IDM | Q20: D-Version | R20: Schubert | S20: Blue Sun | T20: Dalia | U20: Pop Arabia | V20: Zeplin | W20: CMRRA | X20: MLC | Y20: SADAIC | Z20: Latin Autor (Processed by BO) | AA20: ABRAMUS | AB20: Latin Autor (Processed by BO) | AC20: Latin Autor (Processed by BO) | AD20: Latin Autor (Processed by BO) | AE20: Latin Autor (Processed by BO) | AF20: SACM | AG20: Latin Autor (Processed by BO) | AH20: Latin Autor (Processed by BO) | AI20: Latin Autor (Processed by BO) | AJ20: APRA-AMCOS | AK20: APRA-AMCOS | AL20: MCSC | AM20: CASH | AN20: IPRS | AO20: JASRAC | AP20: MACP | AQ20: FILSCAP | AR20: VCPMC | AS20: MCT | AT20: COMPASS | AU20: KOMCA | AX20: CAPASSO
B21: SGAE | C21: Kobalt Paid By | D21: AUME | E21: SABAM | F21: SACEM | G21: GEMA | H21: SIAE | I21: BUMA | J21: Nordic Sources | K21: SPA | L21: SGAE | M21: STIM | N21: SUISA | O21: MCPS-PRS | P21: IDM | Q21: D-Version | R21: Schubert | S21: Blue Sun | T21: Dalia | U21: Pop Arabia | V21: Zeplin | W21: CMRRA | X21: MLC | Y21: SADAIC | Z21: No Membership | AA21: ABRAMUS | AB21: Latin Autor | AC21: Latin Autor | AD21: Latin Autor | AE21: Latin Autor | AF21: SACM | AG21: No Membership | AH21: Latin Autor | AI21: Latin Autor | AJ21: APRA-AMCOS | AK21: APRA-AMCOS | AL21: CASH | AM21: CASH | AN21: Turnkey | AO21: SMPJ | AP21: Indie Works | AQ21: COMPASS | AR21: COMPASS | AS21: COMPASS | AT21: COMPASS | AU21: EKKO | AX21: CAPASSO
A22: SIAE | B22: SIAE | C22: Licensed By | D22: AKM | E22: SABAM | F22: SACEM | G22: GEMA | H22: SIAE | I22: BUMA | J22: Nordic Sources | K22: SPA | L22: SGAE | M22: STIM | N22: SUISA | O22: MCPS-PRS | P22: QUERY SOURCE/ TERR OWNER | Q22: QUERY SOURCE/ TERR OWNER | R22: QUERY SOURCE/ TERR OWNER | S22: RAO | T22: ACUM | U22: ESMAA | V22: MSG | W22: CMRRA | X22: MLC | Y22: SADAIC | Z22: Latin Autor | AA22: ABRAMUS | AB22: Latin Autor | AC22: Latin Autor | AD22: Latin Autor | AE22: Latin Autor | AF22: SACM | AG22: Latin Autor | AH22: Latin Autor | AI22: Latin Autor | AJ22: APRA-AMCOS | AK22: APRA-AMCOS | AL22: MCSC | AM22: CASH | AN22: IPRS | AO22: JASRAC | AP22: MACP | AQ22: FILSCAP | AR22: VCPMC | AS22: MCT | AT22: COMPASS | AU22: KOMCA | AV22: WAMI | AW22: MUST | AX22: SAMRO | AY22: QUERY SOURCE/ TERR OWNER
B23: SIAE | C23: Licensor Pays | D23: AKM | E23: SABAM | F23: SACEM | G23: GEMA | H23: SIAE | I23: BUMA | J23: Nordic Sources | K23: SPA | L23: SGAE | M23: STIM | N23: SUISA | O23: MCPS-PRS | P23: QUERY SOURCE/ TERR OWNER | Q23: QUERY SOURCE/ TERR OWNER | R23: QUERY SOURCE/ TERR OWNER | S23: Blue Sun | T23: Dalia | U23: Pop Arabia | V23: Zeplin | W23: CMRRA | X23: MLC | Y23: SADAIC | Z23: Latin Autor (Processed by BO) | AA23: ABRAMUS | AB23: Latin Autor (Processed by BO) | AC23: Latin Autor (Processed by BO) | AD23: Latin Autor (Processed by BO) | AE23: Latin Autor (Processed by BO) | AF23: SACM | AG23: Latin Autor (Processed by BO) | AH23: Latin Autor (Processed by BO) | AI23: Latin Autor (Processed by BO) | AJ23: APRA-AMCOS | AK23: APRA-AMCOS | AL23: MCSC | AM23: CASH | AN23: IPRS | AO23: JASRAC | AP23: MACP | AQ23: FILSCAP | AR23: VCPMC | AS23: MCT | AT23: COMPASS | AU23: KOMCA | AV23: WAMI | AW23: MUST | AX23: SAMRO | AY23: QUERY SOURCE/ TERR OWNER
B24: SIAE | C24: Kobalt Paid By | D24: AKM | E24: SABAM | F24: SACEM | G24: GEMA | H24: SIAE | I24: BUMA | J24: Nordic Sources | K24: SPA | L24: SGAE | M24: STIM | N24: SUISA | O24: MCPS-PRS | P24: IDM | Q24: D-Version | R24: Schubert | S24: Blue Sun | T24: Dalia | U24: Pop Arabia | V24: Zeplin | W24: CMRRA | X24: MLC | Y24: SADAIC | Z24: No Membership | AA24: ABRAMUS | AB24: Latin Autor | AC24: Latin Autor | AD24: Latin Autor | AE24: Latin Autor | AF24: SACM | AG24: No Membership | AH24: Latin Autor | AI24: Latin Autor | AJ24: APRA-AMCOS | AK24: APRA-AMCOS | AL24: CASH | AM24: CASH | AN24: Turnkey | AO24: SMPJ | AP24: Indie Works | AQ24: COMPASS | AR24: COMPASS | AS24: COMPASS | AT24: COMPASS | AU24: EKKO | AV24: PT Nadaku | AW24: One Asia | AX24: SAMRO | AY24: QUERY SOURCE/ TERR OWNER
A25: SPA | B25: SPA | C25: Licensed By | D25: AUME | E25: SABAM | F25: SACEM | G25: GEMA | H25: SIAE | I25: BUMA | J25: STIM | K25: SPA | L25: SGAE | M25: STIM | N25: SUISA | O25: MCPS-PRS | P25: HDS-ZAMP | Q25: AUTODIA | R25: ZAIKS | S25: RAO | T25: ACUM | U25: ESMAA | V25: MSG | W25: CMRRA | X25: MLC | Y25: SADAIC | Z25: Latin Autor | AA25: ABRAMUS | AB25: Latin Autor | AC25: Latin Autor | AD25: Latin Autor | AE25: Latin Autor | AF25: SACM | AG25: Latin Autor | AH25: Latin Autor | AI25: Latin Autor | AJ25: APRA-AMCOS | AK25: APRA-AMCOS | AM25: CASH | AO25: JASRAC | AP25: MACP | AQ25: FILSCAP | AR25: VCPMC | AS25: MCT | AU25: KOMCA | AW25: MUST | AX25: CAPASSO
B26: SPA | C26: Licensor Pays | D26: AUME | E26: SABAM | F26: SACEM | G26: GEMA | H26: SIAE | I26: BUMA | J26: STIM | K26: SPA | L26: SGAE | M26: STIM | N26: SUISA | O26: MCPS-PRS | P26: IDM | Q26: D-Version | R26: Schubert | S26: Blue Sun | T26: Dalia | U26: Pop Arabia | V26: Zeplin | W26: CMRRA | X26: MLC | Y26: SADAIC | Z26: Latin Autor (Processed by BO) | AA26: ABRAMUS | AB26: Latin Autor (Processed by BO) | AC26: Latin Autor (Processed by BO) | AD26: Latin Autor (Processed by BO) | AE26: Latin Autor (Processed by BO) | AF26: SACM | AG26: Latin Autor (Processed by BO) | AH26: Latin Autor (Processed by BO) | AI26: Latin Autor (Processed by BO) | AJ26: APRA-AMCOS | AK26: APRA-AMCOS | AM26: CASH | AO26: JASRAC | AP26: MACP | AQ26: FILSCAP | AR26: VCPMC | AS26: MCT | AU26: KOMCA | AW26: MUST | AX26: CAPASSO
B27: SPA | C27: Kobalt Paid By | D27: AUME | E27: SABAM | F27: SACEM | G27: GEMA | H27: SIAE | I27: BUMA | J27: STIM | K27: SPA | L27: SGAE | M27: STIM | N27: SUISA | O27: MCPS-PRS | P27: IDM | Q27: D-Version | R27: Schubert | S27: Blue Sun | T27: Dalia | U27: Pop Arabia | V27: Zeplin | W27: CMRRA | X27: MLC | Y27: SADAIC | Z27: No Membership | AA27: ABRAMUS | AB27: Latin Autor | AC27: Latin Autor | AD27: Latin Autor | AE27: Latin Autor | AF27: SACM | AG27: No Membership | AH27: Latin Autor | AI27: Latin Autor | AJ27: APRA-AMCOS | AK27: APRA-AMCOS | AM27: CASH | AO27: SMPJ | AP27: Indie Works | AQ27: COMPASS | AR27: COMPASS | AS27: Compass | AU27: EKKO | AW27: One Asia | AX27: CAPASSO
A28: STIM-NCB | B28: STIM-NCB | C28: Licensed By | D28: ICE | E28: ICE | F28: ICE | G28: ICE | H28: ICE | I28: ICE | J28: ICE | K28: ICE | L28: ICE | M28: ICE | N28: ICE | O28: ICE | P28: ICE | Q28: ICE | R28: ICE | S28: RAO | T28: ACUM | U28: ESMAA | V28: MSG | W28: CMRRA | X28: MLC | Y28: SADAIC | Z28: Latin Autor | AA28: ABRAMUS | AB28: Latin Autor | AC28: Latin Autor | AD28: Latin Autor | AE28: Latin Autor | AF28: SACM | AG28: Latin Autor | AH28: Latin Autor | AI28: Latin Autor | AJ28: APRA-AMCOS | AK28: APRA-AMCOS | AL28: APRA-AMCOS | AM28: APRA-AMCOS | AN28: APRA-AMCOS | AO28: APRA-AMCOS | AP28: APRA-AMCOS | AQ28: APRA-AMCOS | AR28: APRA-AMCOS | AS28: APRA-AMCOS | AT28: APRA-AMCOS | AU28: APRA-AMCOS | AV28: APRA-AMCOS | AW28: APRA-AMCOS | AX28: CAPASSO | AY28: ICE
B29: STIM-NCB | C29: Licensor Pays | D29: STIM | E29: STIM | F29: STIM | G29: STIM | H29: STIM | I29: STIM | J29: STIM | K29: STIM | L29: STIM | M29: STIM | N29: STIM | O29: STIM | P29: STIM | Q29: STIM | R29: STIM | S29: Blue Sun | T29: Dalia | U29: Pop Arabia | V29: Zeplin | W29: CMRRA | X29: MLC | Y29: SADAIC | Z29: Latin Autor (Processed by BO) | AA29: ABRAMUS | AB29: Latin Autor (Processed by BO) | AC29: Latin Autor (Processed by BO) | AD29: Latin Autor (Processed by BO) | AE29: Latin Autor (Processed by BO) | AF29: SACM | AG29: Latin Autor (Processed by BO) | AH29: Latin Autor (Processed by BO) | AI29: Latin Autor (Processed by BO) | AJ29: APRA-AMCOS | AK29: APRA-AMCOS | AL29: STIM | AM29: STIM | AN29: STIM | AO29: STIM | AP29: STIM | AQ29: STIM | AR29: STIM | AS29: STIM | AT29: STIM | AU29: STIM | AV29: STIM | AW29: STIM | AX29: CAPASSO | AY29: STIM
B30: STIM-NCB | C30: Kobalt Paid By | D30: STIM | E30: STIM | F30: STIM | G30: STIM | H30: STIM | I30: STIM | J30: STIM | K30: STIM | L30: STIM | M30: STIM | N30: STIM | O30: STIM | P30: IDM | Q30: D-Version | R30: Schubert | S30: Blue Sun | T30: Dalia | U30: Pop Arabia | V30: Zeplin | W30: CMRRA | X30: MLC | Y30: SADAIC | Z30: No Membership | AA30: ABRAMUS | AB30: Latin Autor | AC30: Latin Autor | AD30: Latin Autor | AE30: Latin Autor | AF30: SACM | AG30: No Membership | AH30: Latin Autor | AI30: Latin Autor | AJ30: APRA-AMCOS | AK30: APRA-AMCOS | AL30: STIM | AM30: STIM | AN30: Turnkey | AO30: SMPJ | AP30: Indie Works | AQ30: STIM | AR30: STIM | AS30: STIM | AT30: STIM | AU30: EKKO | AV30: PT Nadaku | AW30: One Asia | AX30: CAPASSO | AY30: STIM
A31: SUISA | B31: SUISA | C31: Licensed By | D31: MINT / ICE | E31: MINT / ICE | F31: MINT / ICE | G31: MINT / ICE | H31: MINT / ICE | I31: MINT / ICE | J31: MINT / ICE | K31: MINT / ICE | L31: MINT / ICE | M31: MINT / ICE | N31: SUISA | O31: MINT / ICE | P31: MINT / ICE | Q31: MINT / ICE | R31: MINT / ICE | S31: RAO | T31: ACUM | U31: ESMAA | V31: MSG | W31: CMRRA | X31: MLC | Y31: SADAIC | Z31: Latin Autor | AA31: ABRAMUS | AB31: Latin Autor | AD31: Latin Autor | AE31: Latin Autor | AF31: SACM | AH31: APDAYC | AI31: AGADU | AJ31: APRA-AMCOS | AK31: APRA-AMCOS | AL31: MCSC | AM31: CASH | AN31: IPRS | AO31: JASRAC | AP31: MACP | AR31: VCPMC | AS31: MCT | AT31: COMPASS | AV31: WAMI | AW31: MUST | AX31: CAPASSO
B32: SUISA | C32: Licensor Pays | D32: AUME | E32: SABAM | F32: SACEM | G32: GEMA | H32: SIAE | I32: STEMRA | J32: STIM | K32: SPA | L32: SGAE | M32: STIM | N32: SUISA | O32: MCPS-PRS | P32: HDS ZAMP | Q32: AUTODIA | R32: ZAIKS | S32: Blue Sun | T32: Dalia | U32: Pop Arabia | V32: Zeplin | W32: CMRRA | X32: MLC | Y32: SADAIC | Z32: Latin Autor (Processed by BO) | AA32: ABRAMUS | AB32: Latin Autor (Processed by BO) | AD32: Latin Autor (Processed by BO) | AE32: Latin Autor (Processed by BO) | AF32: SACM | AH32: Latin Autor (Processed by BO) | AI32: Latin Autor (Processed by BO) | AJ32: APRA-AMCOS | AK32: APRA-AMCOS | AL32: MCSC | AM32: CASH | AN32: IPRS | AO32: JASRAC | AP32: MACP | AR32: VCPMC | AS32: MCT | AT32: COMPASS | AV32: WAMI | AW32: MUST | AX32: CAPASSO
